Workbook
Name Clasificacion: Validaciones!$B$2:$B$35
Name Partida: Validaciones!$C$2:$C$35
Name SS: Validaciones!$A$2:$A$35

Sheet 1_Resumen
C1: DEPARTAMENTO DE MONITOREO DE OBRAS
C3: Informe Técnico Consolidado de Notas de Cambio
A7: Clasificación
A8: Errores de Diseño | D8: =COUNTIF('2_Notas de Cambio'!E:E,A8) -> 1312
A9: Funcionalidad | D9: =COUNTIF('2_Notas de Cambio'!E:E,A9) -> 627
A10: OGUC, SERVIU | D10: =COUNTIF('2_Notas de Cambio'!E:E,A10) -> 0
A11: AS/NTB | D11: =COUNTIF('2_Notas de Cambio'!E:E,A11) -> 223
A12: Total | D12: =SUM(D8:D11) -> 2162
A26: Partidas
A27: Obras Previas | D27: =COUNTIF('2_Notas de Cambio'!F:F,A27) -> 35
A28: Obra Gruesa | D28: =COUNTIF('2_Notas de Cambio'!F:F,A28) -> 398
A29: Terminaciones | D29: =COUNTIF('2_Notas de Cambio'!F:F,A29) -> 732
A30: Instalaciones/Eléctricas | D30: =COUNTIF('2_Notas de Cambio'!F:F,A30) -> 324
A31: Instalaciones/Sanitaria | D31: =COUNTIF('2_Notas de Cambio'!F:F,A31) -> 261
A32: Instalaciones/Gases Clínicos | D32: =COUNTIF('2_Notas de Cambio'!F:F,A32) -> 43
A33: Instalaciones/Climatización | D33: =COUNTIF('2_Notas de Cambio'!F:F,A33) -> 142
A34: Instalaciones/Gas | D34: =COUNTIF('2_Notas de Cambio'!F:F,A34) -> 11
A35: Instalaciones/Control Centralizado | D35: =COUNTIF('2_Notas de Cambio'!F:F,A35) -> 16
A36: Instalaciones/Seguridad | D36: =COUNTIF('2_Notas de Cambio'!F:F,A36) -> 64
A37: Instalaciones/Ascensores | D37: =COUNTIF('2_Notas de Cambio'!F:F,A37) -> 4
A38: Instalaciones/Corrientes Débiles | D38: =COUNTIF('2_Notas de Cambio'!F:F,A38) -> 81
A39: Obras Exteriores | D39: =COUNTIF('2_Notas de Cambio'!F:F,A39) -> 66
A40: Total | D40: =SUM(D27:D39) -> 2177

Sheet 2_Notas de Cambio
A1: SERVICIO DE SALUD | B1: NOMBRE DEL PROYECTO | C1: N° NC | D1: DESCRIPCIÓN | E1: Clasificación | F1: Partida | G1: AUMENTO CON IVA | H1: DISMINUCIÓN CON IVA | I1: OBRA EXTRAORDINARIA CON IVA | J1: SUBTOTAL | K1: AUMENTO DE PLAZO | L1: INDEMNIZACIÓN POR PLAZO CON IVA | M1: TOTAL | N1: ORD DE INGRESO NC SS A MINSAL | O1: C4 MINSAL RESPUESTA A SS | P1: FECHA INGRESO DE NC DEL SS A MINSAL | Q1: VALOR UF (ORD ingreso) | R1: Total UF
A2: 23 Araucanía Norte | B2: Normalizacion Hospital Lonquimay (MOP) | C2: PROYECTO MODIFICADO CLIMATIZACIÓN | D2: Se instalan bombas de recirculación de agua caliente y fría para las instalaciones proyectadas. Bombas centrífugas en base o en línea. Se proyectan coelctores solares térmicos para apoyar el calentamiento del agua sanitaria de modo de disminuir el consumo de gas y/o pellets. | E2: Errores de Diseño | F2: Instalaciones/Eléctricas | G2: 76447354 | H2: 242745203 | I2: 814529295 | J2: =+G2-H2+I2 -> 648231446 | K2: 0 | L2: 0 | M2: =+J2+L2 -> 648231446 | N2: ord. 813 del 06-06-22 | O2: 2259 | P2: 44718 | Q2: 32767.6 | R2: =M2/Q2 -> 19782.695
A3: 23 Araucanía Norte | B3: Normalizacion Hospital Lonquimay (MOP) | C3: PRESUPUESTO MODIFICADO ELÉCTRICO | D3: Misma descripción que mosidifación anterior, pero con observaciones que modifica montos de esta. | E3: Errores de Diseño | F3: Instalaciones/Eléctricas | G3: 17818702 | H3: 439856261 | I3: 826624974 | J3: =+G3-H3+I3 -> 404587415 | K3: 0 | L3: 0 | M3: =+J3+L3 -> 404587415 | N3: ord. 813 del 06-06-22 | O3: 2259 | P3: 44718 | Q3: 32767.6 | R3: =M3/Q3 -> 12347.179
A4: 23 Araucanía Norte | B4: Normalizacion Hospital Lonquimay (MOP) | C4: PRESUPUESTO MODIFICADO ELÉCTRICO | D4: Subestación eléctrica del edificio de 1000KA estará compuesta por un transformador Paud Mounted, con las celdas de conexión a M.T. y B. T. EL transformador trifásico 13.2/0.4 KV refrigerado en silicona. Línea generalizada desde tablero gral. Está definido de acuerdo a estudio desarrollado del proyecto modificado. | E4: Errores de Diseño | F4: Instalaciones/Eléctricas | G4: 61301441 | H4: 324174468 | I4: 1334055899 | J4: =+G4-H4+I4 -> 1071182872 | K4: 0 | L4: 0 | M4: =+J4+L4 -> 1071182872 | N4: ord. 813 del 06-06-22 | O4: 2259 | P4: 44718 | Q4: 32767.6 | R4: =M4/Q4 -> 32690.306
A5: 23 Araucanía Norte | B5: Normalizacion Hospital Lonquimay (MOP) | C5: OBRA EXTRAORDINARIO Nº 58 | D5: ETAPA 3 PROTECCIÓN SOLAR O DE PRIVACIDAD. | E5: AS/NTB | F5: Terminaciones | G5: 25292754 | H5: 0 | I5: 2150407 | J5: =+G5-H5+I5 -> 27443161 | K5: 0 | L5: 0 | M5: =+J5+L5 -> 27443161 | N5: 0rd. 79 del 17-01-23 | O5: 273 | P5: 44943 | Q5: 35239.79 | R5: =M5/Q5 -> 778.75495
A6: 23 Araucanía Norte | B6: Normalizacion Hospital Lonquimay (MOP) | C6: OBRA EXTRAORDINARIO Nº 57 | D6: ETAPA 3 FICHA N°44 REAS. | E6: AS/NTB | F6: Terminaciones | G6: 5564804 | H6: 0 | I6: 1044525 | J6: =+G6-H6+I6 -> 6609329 | K6: 0 | L6: 0 | M6: =+J6+L6 -> 6609329 | N6: 0rd. 79 del 17-01-23 | O6: 273 | P6: 44943 | Q6: 35239.79 | R6: =M6/Q6 -> 187.55302
A7: 22 Araucanía Sur | B7: NORMALIZACIÓN HOSPITAL COMUNITARIO Y FAMILIAR DR. EDUARDO GONZALEZ G, CUNCO | C7: 1.23 | D7: Instalaciones Domiciliarias afectadas | E7: AS/NTB | F7: Instalaciones/Sanitaria | G7: 0 | H7: 0 | I7: 0 | J7: =+G7-H7+I7 -> 0 | L7: 0 | M7: =+J7+L7 -> 0 | N7: ORD. N° 1823 del 29-05-17 | O7: C4/ 2192 del 28-06-17 | P7: 42884 | Q7: 26627.55 | R7: =M7/Q7 -> 0
A8: 22 Araucanía Sur | B8: NORMALIZACIÓN HOSPITAL COMUNITARIO Y FAMILIAR DR. EDUARDO GONZALEZ G, CUNCO | C8: 1.23.4 | D8: GLP | E8: AS/NTB | F8: Instalaciones/Climatización | G8: 0 | H8: 0 | I8: 0 | J8: =+G8-H8+I8 -> 0 | K8: 20 | L8: 0 | M8: =+J8+L8 -> 0 | N8: ORD. N° 1823 del 29-05-17 | O8: C4/ 2192 del 28-06-17 | P8: 42884 | Q8: 26627.55 | R8: =M8/Q8 -> 0
A9: 23 Araucanía Norte | B9: Normalizacion Hospital Lonquimay (MOP) | C9: OBRA EXTRAORDINARIO Nº 56 - FICHA 42 | D9: ETAPA 3 FICHA N°42 DENTAL. | E9: AS/NTB | F9: Terminaciones | G9: 15897894 | H9: 0 | I9: 3329307 | J9: =+G9-H9+I9 -> 19227201 | K9: 0 | L9: 0 | M9: =+J9+L9 -> 19227201 | N9: 0rd. 79 del 17-01-23 | O9: 273 | P9: 44943 | Q9: 35239.79 | R9: =M9/Q9 -> 545.61054
A10: 23 Araucanía Norte | B10: Normalizacion Hospital Lonquimay (MOP) | C10: OBRA EXTRAORDINARIO Nº 55 - FICHA 40 | D10: ETAPA 5 FICHA N°40 ESTERILIZACION. | E10: AS/NTB | F10: Terminaciones | G10: 1053313 | H10: 0 | I10: 883807 | J10: =+G10-H10+I10 -> 1937120 | K10: 0 | L10: 0 | M10: =+J10+L10 -> 1937120 | N10: 0rd. 79 del 17-01-23 | O10: 273 | P10: 44943 | Q10: 35239.79 | R10: =M10/Q10 -> 54.969681
A11: 23 Araucanía Norte | B11: Normalizacion Hospital Lonquimay (MOP) | C11: OBRA EXTRAORDINARIO Nº 54 - FICHA 39 | D11: ETAPA 5 FICHA N°39 ENTREGA CADAVERES. | E11: AS/NTB | F11: Terminaciones | G11: 1226081 | H11: 0 | I11: 294415 | J11: =+G11-H11+I11 -> 1520496 | K11: 0 | L11: 0 | M11: =+J11+L11 -> 1520496 | N11: 0rd. 79 del 17-01-23 | O11: 273 | P11: 44943 | Q11: 35239.79 | R11: =M11/Q11 -> 43.147136
A12: 23 Araucanía Norte | B12: Normalizacion Hospital Lonquimay (MOP) | C12: OBRA EXTRAORDINARIO Nº 53 | D12: ETAPA 5 FICHA N°38 GINECO-OBTETRICO. | E12: AS/NTB | F12: Terminaciones | G12: 0 | H12: 0 | I12: 12938405 | J12: =+G12-H12+I12 -> 12938405 | K12: 0 | L12: 0 | M12: =+J12+L12 -> 12938405 | N12: 0rd. 79 del 17-01-23 | O12: 273 | P12: 44943 | Q12: 35239.79 | R12: =M12/Q12 -> 367.15329
A13: 23 Araucanía Norte | B13: Normalizacion Hospital Lonquimay (MOP) | C13: OBRA EXTRAORDINARIO Nº 35 | D13: MODIFICACION REVESTIMIENTO DEL ACCESO DE AMBULANCIAS | E13: Errores de Diseño | F13: Terminaciones | G13: 614787 | H13: 0 | I13: 14139511 | J13: =+G13-H13+I13 -> 14754298 | K13: 0 | L13: 0 | M13: =+J13+L13 -> 14754298 | N13: 0rd. 79 del 17-01-23 | O13: 273 | P13: 44943 | Q13: 35239.79 | R13: =M13/Q13 -> 418.68291
A14: 23 Araucanía Norte | B14: Normalizacion Hospital Lonquimay (MOP) | C14: OBRA EXTRAORDINARIO Nº 27 | D14: MODIFICACION PARA ABASTECIMIENTO AGUA CALIENTE. | E14: Errores de Diseño | F14: Terminaciones | G14: 0 | H14: 1163368 | I14: 12264633 | J14: =+G14-H14+I14 -> 11101265 | K14: 0 | L14: 0 | M14: =+J14+L14 -> 11101265 | N14: 0rd. 79 del 17-01-23 | O14: 273 | P14: 44943 | Q14: 35239.79 | R14: =M14/Q14 -> 315.02075
A15: 23 Araucanía Norte | B15: Normalizacion Hospital Lonquimay (MOP) | C15: OBRA EXTRAORDINARIA TECNICA N°1 | D15: MURO DE CONTENCIÓN | E15: Funcionalidad | F15: Obra Gruesa | G15: 88136732 | H15: 3030990 | I15: 77526755 | J15: =+G15-H15+I15 -> 162632497 | K15: 0 | L15: 0 | M15: =+J15+L15 -> 162632497 | N15: Ord. 1297 del 12-09-22 | O15: 4036 | P15: 44816 | Q15: 34013.91 | R15: =M15/Q15 -> 4781.3526
A16: 23 Araucanía Norte | B16: Normalizacion Hospital Lonquimay (MOP) | C16: OBRA EXTRAORDINARIA Nº 8 | D16: Ficha N°13; Desplazamiento pasa muro en recinto C/1/33, Reubicar Instalación de lavado profundo, Reubicar enchufe computación doble y conexión telefoína y datos recinto C/1/33, Incluir puerta PM90, Redimensionamiento de tabique T1 y T2, Reubicar lavamanos 5, Se requiere redimensionar mueble MTCPC-300-800 para instalar autoclave proyectado e incorporar punto de datos en mesón de registro y entrega. | E16: AS/NTB | F16: Terminaciones | H16: 6132888 | J16: =+G16-H16+I16 -> -6132888 | K16: 0 | L16: 0 | M16: =+J16+L16 -> -6132888 | N16: Ord. 1589 del 08-10-21 | O16: 3997 | P16: 44477 | Q16: 30120.42 | R16: =M16/Q16 -> -203.6123
A17: 23 Araucanía Norte | B17: Normalizacion Hospital Lonquimay (MOP) | C17: OBRA EXTRAORDINARIA Nº 7 | D17: Ficha N°12; Incorporación de mica entre trabajo sucio y limpio, Incorporación de lavado profundo acero inox. De una cubeta, e instalaciones respectivas a estos artefactos. | E17: AS/NTB | F17: Terminaciones | J17: =+G17-H17+I17 -> 0 | K17: 0 | L17: 0 | M17: =+J17+L17 -> 0 | N17: Ord. 1589 del 08-10-21 | O17: 3997 | P17: 44477 | Q17: 30120.42 | R17: =M17/Q17 -> 0
A18: 23 Araucanía Norte | B18: Normalizacion Hospital Lonquimay (MOP) | C18: OBRA EXTRAORDINARIA Nº 68 | D18: ETAPA 3 FICHA N°43 EXTRACTORES. | E18: AS/NTB | F18: Terminaciones | G18: 2906579 | H18: 0 | I18: 4518987 | J18: =+G18-H18+I18 -> 7425566 | K18: 0 | L18: 0 | M18: =+J18+L18 -> 7425566 | N18: 0rd. 79 del 17-01-23 | O18: 273 | P18: 44943 | Q18: 35239.79 | R18: =M18/Q18 -> 210.71539
A19: 23 Araucanía Norte | B19: Normalizacion Hospital Lonquimay (MOP) | C19: OBRA EXTRAORDINARIA Nº 67 | D19: ETAPA 3 FICHA N°45 LABORATORIO BODEGA DE REACTIVOS C-128 | E19: AS/NTB | F19: Terminaciones | G19: 0 | H19: 0 | I19: 23510205 | J19: =+G19-H19+I19 -> 23510205 | K19: 0 | L19: 0 | M19: =+J19+L19 -> 23510205 | N19: 0rd. 79 del 17-01-23 | O19: 273 | P19: 44943 | Q19: 35239.79 | R19: =M19/Q19 -> 667.14941
A20: 23 Araucanía Norte | B20: Normalizacion Hospital Lonquimay (MOP) | C20: OBRA EXTRAORDINARIA Nº 66 | D20: ETAPA 5 FICHA N°17 DOSIS UNITARIA/BODEGA ACTIVA. | E20: AS/NTB | F20: Terminaciones | G20: 2819198 | H20: 0 | I20: 2407344 | J20: =+G20-H20+I20 -> 5226542 | K20: 0 | L20: 0 | M20: =+J20+L20 -> 5226542 | N20: 0rd. 79 del 17-01-23 | O20: 273 | P20: 44943 | Q20: 35239.79 | R20: =M20/Q20 -> 148.31365
A21: 23 Araucanía Norte | B21: Normalizacion Hospital Lonquimay (MOP) | C21: OBRA EXTRAORDINARIA Nº 65 | D21: ETAPA 3 FICHA N°41 RAYOS. | E21: AS/NTB | F21: Terminaciones | G21: 8103146 | H21: 0 | I21: 8032405 | J21: =+G21-H21+I21 -> 16135551 | K21: 0 | L21: 0 | M21: =+J21+L21 -> 16135551 | N21: 0rd. 79 del 17-01-23 | O21: 273 | P21: 44943 | Q21: 35239.79 | R21: =M21/Q21 -> 457.87875
A22: 23 Araucanía Norte | B22: Normalizacion Hospital Lonquimay (MOP) | C22: OBRA EXTRAORDINARIA Nº 64 | D22: ETAPA 5 FICHA N°37 URGENCIAS. | E22: AS/NTB | F22: Terminaciones | G22: 6478542 | H22: 0 | I22: 5841408 | J22: =+G22-H22+I22 -> 12319950 | K22: 0 | L22: 0 | M22: =+J22+L22 -> 12319950 | N22: 0rd. 79 del 17-01-23 | O22: 273 | P22: 44943 | Q22: 35239.79 | R22: =M22/Q22 -> 349.60339
A23: 23 Araucanía Norte | B23: Normalizacion Hospital Lonquimay (MOP) | C23: OBRA EXTRAORDINARIA Nº 62 | D23: ETAPA 3 FICHA N°18 PUERTA CENTRAL DE ALIMENTACION. | E23: AS/NTB | F23: Terminaciones | G23: 2183621 | H23: 0 | I23: 553662 | J23: =+G23-H23+I23 -> 2737283 | K23: 0 | L23: 0 | M23: =+J23+L23 -> 2737283 | N23: 0rd. 79 del 17-01-23 | O23: 273 | P23: 44943 | Q23: 35239.79 | R23: =M23/Q23 -> 77.675917
A24: 23 Araucanía Norte | B24: Normalizacion Hospital Lonquimay (MOP) | C24: OBRA EXTRAORDINARIA Nº 61 | D24: ETAPA 5 FICHA N°14 SEDILE. | E24: AS/NTB | F24: Terminaciones | G24: 3866375 | H24: 0 | I24: 2951680 | J24: =+G24-H24+I24 -> 6818055 | K24: 0 | L24: 0 | M24: =+J24+L24 -> 6818055 | N24: 0rd. 79 del 17-01-23 | O24: 273 | P24: 44943 | Q24: 35239.79 | R24: =M24/Q24 -> 193.47604
A25: 23 Araucanía Norte | B25: Normalizacion Hospital Lonquimay (MOP) | C25: OBRA EXTRAORDINARIA Nº 6 | D25: Ficha N°10 se requieren las siguientes modificaciones, en Recinto Rx se incluye señalética de advertencia RC universal | E25: AS/NTB | F25: Terminaciones | J25: =+G25-H25+I25 -> 0 | K25: 0 | L25: 0 | M25: =+J25+L25 -> 0 | N25: Ord. 1589 del 08-10-21 | O25: 3997 | P25: 44477 | Q25: 30120.42 | R25: =M25/Q25 -> 0
A26: 23 Araucanía Norte | B26: Normalizacion Hospital Lonquimay (MOP) | C26: OBRA EXTRAORDINARIA Nº 56 - FICHA 8 | D26: ETAPA 3 FICHA N°8 LAVANDERIA. | E26: AS/NTB | F26: Terminaciones | G26: 132773 | H26: 0 | I26: 1287549 | J26: =+G26-H26+I26 -> 1420322 | K26: 0 | L26: 0 | M26: =+J26+L26 -> 1420322 | N26: 0rd. 79 del 17-01-23 | O26: 273 | P26: 44943 | Q26: 35239.79 | R26: =M26/Q26 -> 40.304497
A27: 23 Araucanía Norte | B27: Normalizacion Hospital Lonquimay (MOP) | C27: OBRA EXTRAORDINARIA Nº 55 - FICHA 7 | D27: ETAPA 3 FICHA N°7 ESTERILIZACION. | E27: AS/NTB | F27: Terminaciones | G27: 10684208 | H27: 0 | I27: 12731434 | J27: =+G27-H27+I27 -> 23415642 | K27: 0 | L27: 0 | M27: =+J27+L27 -> 23415642 | N27: 0rd. 79 del 17-01-23 | O27: 273 | P27: 44943 | Q27: 35239.79 | R27: =M27/Q27 -> 664.46599
A28: 23 Araucanía Norte | B28: Normalizacion Hospital Lonquimay (MOP) | C28: OBRA EXTRAORDINARIA Nº 54 - FICHA 3 | D28: ETAPA 3 FICHA N°3 ENCHUFES PARA CATRES CLINICOS. | E28: AS/NTB | F28: Instalaciones/Eléctricas | G28: 0 | H28: 0 | I28: 1753112 | J28: =+G28-H28+I28 -> 1753112 | K28: 0 | L28: 0 | M28: =+J28+L28 -> 1753112 | N28: 0rd. 79 del 17-01-23 | O28: 273 | P28: 44943 | Q28: 35239.79 | R28: =M28/Q28 -> 49.748083
A29: 23 Araucanía Norte | B29: Normalizacion Hospital Lonquimay (MOP) | C29: OBRA EXTRAORDINARIA Nº 5 | D29: Ficha N°9; Eliminación artefactos de trabajo sucio N°18 logrando área para camilla. Reemplazo de WC infantil con estanque por WC universal con descarga a piso con flujómetro oculto y reubicar, reemplazar lavamanos mural para nicños por lavamanos universal y reubicación, reubicación de puerta y mudador, desplazar tabique T1 para permitir accesibilidad universal en baño, reemplazar tabiques por cortinas clínicas, reubicar lavamanos de uso clínico con semipedestal en el interior de área disiatría. | E29: AS/NTB | F29: Terminaciones | H29: 2507993 | J29: =+G29-H29+I29 -> -2507993 | K29: 0 | L29: 0 | M29: =+J29+L29 -> -2507993 | N29: Ord. 1589 del 08-10-21 | O29: 3997 | P29: 44477 | Q29: 30120.42 | R29: =M29/Q29 -> -83.265539
A30: 23 Araucanía Norte | B30: Normalizacion Hospital Lonquimay (MOP) | C30: OBRA EXTRAORDINARIA Nº 45 | D30: ETAPA 3, PUNTOS DE DATOS. | E30: AS/NTB | F30: Instalaciones/Eléctricas | G30: 10886540 | H30: 0 | I30: 7815153 | J30: =+G30-H30+I30 -> 18701693 | K30: 0 | L30: 0 | M30: =+J30+L30 -> 18701693 | N30: 0rd. 79 del 17-01-23 | O30: 273 | P30: 44943 | Q30: 35239.79 | R30: =M30/Q30 -> 530.6982
A31: 23 Araucanía Norte | B31: Normalizacion Hospital Lonquimay (MOP) | C31: OBRA EXTRAORDINARIA Nº 4 | D31: Ficha N°7; Modifica recintos de atención como abrrera sanitaria entre trbajo sucio y limpio, desplazamiento de enchufe computación doble hacia mueble de registro. Se requiere incorporar preinstalaciones de enchufe refuerzo de soporte , etc, para negatoscopio. Incorporación de enchufse de alumbrado doble, enchufe de computación y desplazar el módulo de punto de registro hacia el eje B. Se requiere desplazar enchufe de computación doble, enchufe de alumbrado doble y punto de datos hacia muro eje B. | E31: AS/NTB | F31: Terminaciones | J31: =+G31-H31+I31 -> 0 | K31: 0 | L31: 0 | M31: =+J31+L31 -> 0 | N31: Ord. 1589 del 08-10-21 | O31: 3997 | P31: 44477 | Q31: 30120.42 | R31: =M31/Q31 -> 0
A32: 23 Araucanía Norte | B32: Normalizacion Hospital Lonquimay (MOP) | C32: OBRA EXTRAORDINARIA Nº 3 | D32: Ficha N°6; Incorporación de lavadero mural mural botaguas de aseo, en recinto lavachatas, modificar la ubicación de gabinete colgante con puertas opacas, incluir 2 repisas mural por chata, incluir mica separadora como barrera sanitaria entre trabajo sucio y limpio. | E32: AS/NTB | F32: Terminaciones | H32: 414209 | J32: =+G32-H32+I32 -> -414209 | K32: 0 | L32: 0 | M32: =+J32+L32 -> -414209 | N32: Ord. 1589 del 08-10-21 | O32: 3997 | P32: 44477 | Q32: 30120.42 | R32: =M32/Q32 -> -13.751767
A33: 23 Araucanía Norte | B33: Normalizacion Hospital Lonquimay (MOP) | C33: OBRA EXTRAORDINARIA Nº 2 | D33: Ficha N°4; Configuración de un baño, incorporación de un lavadero mural para botaguas de aseo, incluir repisas murales para chata e incorporar mudador vertical. | E33: AS/NTB | F33: Terminaciones | H33: 5022846 | J33: =+G33-H33+I33 -> -5022846 | K33: 0 | L33: 0 | M33: =+J33+L33 -> -5022846 | N33: Ord. 1589 del 08-10-21 | O33: 3997 | P33: 44477 | Q33: 30120.42 | R33: =M33/Q33 -> -166.75883
A34: 23 Araucanía Norte | B34: Normalizacion Hospital Lonquimay (MOP) | C34: OBRA EXTRAORDINARIA Nº 1 | D34: Ficha N°3; Instalación de mallas mosquiteras en comedor, instalación de enchufe para nuevo refrigerador, reubicación de otro enchufe y aumento de cabida eléctrica de protección eléctrica. | E34: AS/NTB | F34: Terminaciones | J34: =+G34-H34+I34 -> 0 | K34: 0 | L34: 0 | M34: =+J34+L34 -> 0 | N34: Ord. 1589 del 08-10-21 | O34: 3997 | P34: 44477 | Q34: 30120.42 | R34: =M34/Q34 -> 0
A35: 23 Araucanía Norte | B35: Normalizacion Hospital Lonquimay (MOP) | C35: OBRA EXTRAORDINARIA N°52 | D35: PRVACIDAD Y PROTECCION SOLAR VENTANAS | E35: AS/NTB | F35: Terminaciones | G35: 18548019 | H35: 0 | I35: 7716281 | J35: =+G35-H35+I35 -> 26264300 | K35: 0 | L35: 0 | M35: =+J35+L35 -> 26264300 | N35: Ord. 1297 del 12-09-22 | O35: 4036 | P35: 44816 | Q35: 34013.91 | R35: =M35/Q35 -> 772.16351
A36: 23 Araucanía Norte | B36: Normalizacion Hospital Lonquimay (MOP) | C36: OBRA EXTRAORDINARIA N°51 | D36: FICHA N°51 SALA CUNA | E36: AS/NTB | F36: Terminaciones | G36: 1497479 | H36: 186851 | I36: 321043 | J36: =+G36-H36+I36 -> 1631671 | K36: 0 | L36: 0 | M36: =+J36+L36 -> 1631671 | N36: Ord. 1297 del 12-09-22 | O36: 4036 | P36: 44816 | Q36: 34013.91 | R36: =M36/Q36 -> 47.970698
A37: 23 Araucanía Norte | B37: Normalizacion Hospital Lonquimay (MOP) | C37: OBRA EXTRAORDINARIA N°50 | D37: FICHA N°36 CIRUGIA MENOR | E37: AS/NTB | F37: Terminaciones | G37: 2319796 | H37: 0 | I37: 0 | J37: =+G37-H37+I37 -> 2319796 | K37: 0 | L37: 0 | M37: =+J37+L37 -> 2319796 | N37: Ord. 1297 del 12-09-22 | O37: 4036 | P37: 44816 | Q37: 34013.91 | R37: =M37/Q37 -> 68.201392
A38: 23 Araucanía Norte | B38: Normalizacion Hospital Lonquimay (MOP) | C38: OBRA EXTRAORDINARIA N°49 | D38: FICHA N°35 REAS | E38: AS/NTB | F38: Terminaciones | G38: 2557957 | H38: 0 | I38: 1963755 | J38: =+G38-H38+I38 -> 4521712 | K38: 0 | L38: 0 | M38: =+J38+L38 -> 4521712 | N38: Ord. 1297 del 12-09-22 | O38: 4036 | P38: 44816 | Q38: 34013.91 | R38: =M38/Q38 -> 132.93714
A39: 23 Araucanía Norte | B39: Normalizacion Hospital Lonquimay (MOP) | C39: OBRA EXTRAORDINARIA N°48 | D39: FICHA N°34 SEDILE | E39: AS/NTB | F39: Terminaciones | G39: 2736783 | H39: 0 | I39: 1312186 | J39: =+G39-H39+I39 -> 4048969 | K39: 0 | L39: 0 | M39: =+J39+L39 -> 4048969 | N39: Ord. 1297 del 12-09-22 | O39: 4036 | P39: 44816 | Q39: 34013.91 | R39: =M39/Q39 -> 119.03862
A40: 23 Araucanía Norte | B40: Normalizacion Hospital Lonquimay (MOP) | C40: OBRA EXTRAORDINARIA N°47 | D40: FICHA N°33 ALIMENTACION | E40: AS/NTB | F40: Terminaciones | G40: 0 | H40: 0 | I40: 746610 | J40: =+G40-H40+I40 -> 746610 | K40: 0 | L40: 0 | M40: =+J40+L40 -> 746610 | N40: Ord. 1297 del 12-09-22 | O40: 4036 | P40: 44816 | Q40: 34013.91 | R40: =M40/Q40 -> 21.950137
...

Sheet Validaciones
A1: Servicio de Salud | B1: Clasificación: | C1: Partida:
A2: -Seleccionar- | B2: -Seleccionar- | C2: -Seleccionar-
A3: 01 Arica | B3: Errores de Diseño | C3: Obras Previas
A4: 02 Iquique | B4: Funcionalidad | C4: Obra Gruesa
A5: 03 Antofagasta | B5: Normativa (OGUC, Serviu, etc.) | C5: Terminaciones
A6: 04 Atacama | B6: AS/NTB | C6: Instalaciones/Eléctricas
A7: 05 Coquimbo | C7: Instalaciones/Sanitaria
A8: 06 Aconcagua | C8: Instalaciones/Gases Clínicos
A9: 07 Viña del Mar Quillota | C9: Instalaciones/Climatización
A10: 08 Valparaíso San Antonio | C10: Instalaciones/Gas
A11: 09 Metropolitano Norte | C11: Instalaciones/Control Central
A12: 10 Metropolitano Central | C12: Instalaciones/Seguridad
A13: 11 Metropolitano Oriente | C13: Instalaciones/Ascensores
A14: 12 Metropolitano Occidente | C14: Instalaciones/Corrientes Débiles
A15: 13 Metropolitano Sur | C15: Obras Exteriores
A16: 14 Metropolitano Sur Oriente
A17: 15 O'Higgins
A18: 16 Maule
A19: 17 Ñuble
A20: 18 Concepción
A21: 19 Talcahuano
A22: 20 Bío Bío
A23: 21 Arauco
A24: 22 Araucanía Sur
A25: 23 Araucanía Norte
A26: 24 Valdivia
A27: 25 Reloncaví
... A31: 29 Magallanes

Sheet 3_Validaciones
B1: Servicios de Salud | C1: Origen | D1: Partidas
B2: - SELECCIONAR - | C2: - SELECCIONAR - | D2: - SELECCIONAR -
B3: 01 Arica | C3: Funcionalidad | D3: Instalaciones
B4: 02 Iquique | C4: Errores de Diseño | D4: Instalaciones/Sanitaria
B5: 03 Antofagasta | C5: AS/NTB | D5: Instalaciones/Electricas
B6: 04 Atacama | C6: Normativa(OGUC,SERVIU,NTB,etc) | D6: Instalaciones/Gases Clinicos
B7: 05 Coquimbo | D7: Obra Gruesa
B8: 06 Aconcagua | D8: Terminaciones
B9: 07 Viña del Mar Quillota
B10: 08 Valparaíso San Antonio
B11: 09 Metropolitano Norte
B12: 10 Metropolitano Central
B13: 11 Metropolitano Oriente
B14: 12 Metropolitano Occidente
B15: 13 Metropolitano Sur
B16: 14 Metropolitano Sur Oriente
B17: 15 O'Higgins
B18: 16 Maule
B19: 17 Ñuble
B20: 18 Concepción
... B31: 29 Magallanes
